Workbook

Sheet Бюджет 2026
B2: Доходы и расходы
B4: Продажи
C5: Январь 2024 | D5: Февраль 2024 | E5: Март 2024 | F5: Апрель 2024 | G5: Май 2024 | H5: Июнь 2024 | I5: Июль 2024 | J5: Август 2024 | K5: Сентябрь 2024 | L5: Октябрь 2024 | M5: Ноябрь 2024 | N5: Декабрь 2024 | O5: 2024 | P5: 2025 | Q5: % | R5: =P5 -> 2025 | S5: бюджет 2026 | T5: % | U5: Комментарий | V5: Ответсвенный
B6: Выручка от продаж разработки | C6: 1620120 | D6: 2444220 | E6: 2124600 | F6: 2080780 | G6: 2503840 | H6: 1851790 | I6: 2011800 | J6: 2391230 | K6: 3486230 | L6: 3523630 | M6: 3127680 | N6: 3307890 | O6: 32808910 | P6: 35069180 | Q6: =(P6-O6)/O6 -> 0.068891956 | R6: =P6 -> 35069180 | S6: =P6-P6*0.05+8000000+6000000 -> 47315721 | T6: =(S6-R6)/R6 -> 0.34921093 | U6: пункты 1a,1d, 2 роста прибыли | V6: Макшанова Л.М.
B7: Выручка сервера | C7: 5000 | D7: 5000 | E7: 5000 | F7: 5000 | G7: 5000 | H7: 5000 | I7: 5000 | J7: 5000 | K7: 5000 | L7: 5000 | M7: 5000 | N7: 5000 | O7: 60000 | P7: 215000 | Q7: =(P7-O7)/O7 -> 2.5833333 | R7: =P7 -> 215000 | S7: 400000 | T7: =(S7-R7)/R7 -> 0.86046512 | U7: Поднятие цен + 10 аренд | V7: Макшанова Л.М.
B8: Выручка коробки | C8: 0 | D8: 0 | E8: 0 | F8: 104700 | G8: 0 | H8: 0 | I8: 88128 | J8: 134280 | K8: 44064 | L8: 12000 | M8: 0 | N8: 44064 | O8: 1624218 | P8: 1749780 | Q8: =(P8-O8)/O8 -> 0.077306125 | R8: =P8 -> 1749780 | S8: 2500000 | T8: =(S8-R8)/R8 -> 0.42875104 | U8: Рост из за отсутствия НДС | V8: Макшанова Л.М.
B9: Выручка поддержка | C9: 169700 | D9: 183020 | E9: 189300 | F9: 223790 | G9: 82370 | H9: 112500 | I9: 99200 | J9: 102500 | K9: 110000 | L9: 102500 | M9: 113750 | N9: 83410 | O9: 1572040 | P9: 2371080 | Q9: =(P9-O9)/O9 -> 0.50828223 | R9: =P9 -> 2371080 | S9: 3500000 | T9: =(S9-R9)/R9 -> 0.47612059 | V9: Макшанова Л.М.
B10: Выручка продукты | P10: 500000 | R10: =P10 -> 500000 | S10: 3000000 | T10: =(S10-R10)/R10 -> 5 | U10: пункт 1d роста прибыли | V10: Макшанова Л.М.
B11: Итого выручка: | C11: 2420620 | D11: 3172240 | E11: 2998900 | F11: 3264470 | G11: 2591210 | H11: 1969290 | I11: 2204128 | J11: 2716010 | K11: 3826646 | L11: 3912080 | M11: 3293406 | N11: 3688168 | O11: 36057168 | P11: 39896240 | Q11: =(P11-O11)/O11 -> 0.10647181 | R11: =P11 -> 39896240 | S11: =S6+S7+S8+S9+S10 -> 56715721 | T11: =(S11-R11)/R11 -> 0.42158061
R12: =P12
B13: Себестоимость | R13: =P13
C14: Январь 2024 | D14: Февраль 2024 | E14: Март 2024 | F14: Апрель 2024 | G14: Май 2024 | H14: Июнь 2024 | I14: Июль 2024 | J14: Август 2024 | K14: Сентябрь 2024 | L14: Октябрь 2024 | M14: Ноябрь 2024 | N14: Декабрь 2024 | O14: 2024 | P14: 2025 | R14: =P14 -> 2025 | S14: бюджет 2026
B15: Себестоимость от продаж | C15: 658142.69 | D15: 838233.76 | E15: 784464.24 | F15: 737684.19 | G15: 926060 | H15: 696980.01 | I15: 785160.01 | J15: 850099.99 | K15: 1227780 | L15: 1280520 | M15: 966659.99 | N15: 1104560 | O15: 11245609 | P15: 11159397 | Q15: =(P15-O15)/O15 -> -0.0076663103 | R15: =P15 -> 11159397 | S15: =P15*(1.5) -> 16739095 | T15: =(S15-R15)/R15 -> 0.5 | V15: Сысоев В.С.
B16: Себестоимость коробки | C16: 0 | D16: 0 | E16: 0 | F16: 47154.67 | G16: 0 | H16: 0 | I16: 57288 | J16: 93996 | K16: 28644 | L16: 5400 | M16: 0 | N16: 28644 | O16: 949980.83 | P16: 1041424 | Q16: =(P16-O16)/O16 -> 0.096257911 | R16: =P16 -> 1041424 | S16: =S8/2 -> 1250000 | T16: =(S16-R16)/R16 -> 0.20027962 | V16: Макшанова Л.М.
B17: Итого себестоимость: | C17: 908295.97 | D17: 916995.45 | E17: 858797.63 | F17: 982350.67 | G17: 926060 | H17: 696980.01 | I17: 842448.01 | J17: 1008756.2 | K17: 1362459.1 | L17: 1427273 | M17: 991739.99 | N17: 1269834 | O17: 12191990 | P17: 12192901 | Q17: =(P17-O17)/O17 -> 7.4708066e-05 | R17: =P17 -> 12192901 | S17: =S15+S16 -> 17989095 | T17: =(S17-R17)/R17 -> 0.47537452
B18: Итого прибыль: | C18: 1512324 | D18: 2255244.5 | E18: 2140102.4 | F18: 2282119.3 | G18: 1665150 | H18: 1272310 | I18: 1361680 | J18: 1707253.8 | K18: 2464186.9 | L18: 2484807 | M18: 2301666 | N18: 2418334 | O18: 23865178 | P18: 27703339 | Q18: =(P18-O18)/O18 -> 0.16082684 | R18: =P18 -> 27703339 | S18: =S11-S17 -> 38726626 | T18: =(S18-R18)/R18 -> 0.39790462
B19: Рентабельность: | C19: 0.62476722 | D19: 0.71093125 | E19: 0.71362912 | F19: 0.69907805 | G19: 0.64261484 | H19: 0.64607548 | I19: 0.61778626 | J19: 0.62858893 | K19: 0.64395475 | L19: 0.63516262 | M19: 0.69887102 | N19: 0.65570062 | O19: 0.66187056 | P19: 0.69438471 | Q19: =(P19-O19)/O19 -> 0.049124639 | R19: =P19 -> 0.69438471 | S19: =S18/S11 -> 0.68281995 | T19: =(S19-R19)/R19 -> -0.016654692
R20: =P20
B21: Себестоимость прочая | R21: =P21
C22: Январь 2024 | D22: Февраль 2024 | E22: Март 2024 | F22: Апрель 2024 | G22: Май 2024 | H22: Июнь 2024 | I22: Июль 2024 | J22: Август 2024 | K22: Сентябрь 2024 | L22: Октябрь 2024 | M22: Ноябрь 2024 | N22: Декабрь 2024 | O22: 2024 | P22: 2025 | R22: =P22 -> 2025 | S22: бюджет 2026
B23: Простой | C23: 396200 | D23: 468740 | E23: 267100 | F23: 241360 | G23: 171180 | H23: 165000 | I23: 162590.1 | J23: 120000 | K23: 120000 | L23: 126800 | M23: 120000 | N23: 120000 | O23: 2478970.1 | P23: 1782145 | Q23: =(P23-O23)/O23 -> -0.28109461 | R23: =P23 -> 1782145 | S23: 1000000 | T23: =(S23-R23)/R23 -> -0.43887842 | V23: Сысоев В.С.
B24: Оплата попадосов | C24: 283900 | D24: 219510 | E24: 174300 | F24: 287200 | G24: 158450 | H24: 66100 | I24: 39200 | J24: 17400 | K24: 26500 | L24: 29900 | M24: 11200 | N24: 34900 | O24: 1348560 | P24: 946780 | Q24: =(P24-O24)/O24 -> -0.29793261 | R24: =P24 -> 946780 | S24: 500000 | T24: =(S24-R24)/R24 -> -0.47189421 | V24: Сысоев В.С.
B25: Выплата заработной платы разработка | C25: 32730 | D25: 31500 | E25: 55000 | F25: 116000 | G25: 66300 | H25: 73100 | I25: 255801.38 | J25: 155414 | K25: 152314 | L25: 166961.45 | M25: 137324.08 | N25: 159897 | O25: 1402341.9 | P25: 3492482.9 | Q25: =(P25-O25)/O25 -> 1.4904646 | R25: =P25 -> 3492482.9 | S25: 3000000 | T25: =(S25-R25)/R25 -> -0.14101226 | V25: Сысоев В.С.
B26: Оплата аналитики | C26: 143940 | D26: 169800 | E26: 168620 | F26: 172340 | G26: 192320 | H26: 136840 | I26: 140400 | J26: 176520 | K26: 262480 | L26: 259980 | M26: 202300 | N26: 224160 | O26: 2249700 | P26: 2162440 | Q26: =(P26-O26)/O26 -> -0.038787394 | R26: =P26 -> 2162440 | S26: 3000000 | T26: =(S26-R26)/R26 -> 0.38732173 | V26: Сысоев В.С.
B27: Откат ментам | C27: 107760 | D27: 197150 | E27: 200460 | F27: 213747 | G27: 146260 | H27: 82850 | I27: 89350 | J27: 162100 | K27: 285800 | L27: 287700 | M27: 260820 | N27: 281500 | O27: 2315497 | P27: 2597759 | Q27: =(P27-O27)/O27 -> 0.12190126 | R27: =P27 -> 2597759 | S27: 4000000 | T27: =(S27-R27)/R27 -> 0.53978872 | V27: Павлова Д.И.
B28: Бонус отдела продаж | C28: 0 | D28: 0 | E28: 0 | F28: 0 | G28: 0 | H28: 18000 | I28: 1320 | J28: 0 | K28: 12750 | L28: 0 | M28: 0 | N28: 0 | O28: 32070 | P28: 63343 | Q28: =(P28-O28)/O28 -> 0.97514811 | R28: =P28 -> 63343 | S28: 400000 | T28: =(S28-R28)/R28 -> 5.3148256 | V28: Макшанова Л.М.
B29: Итого Себестоимость прочая: | C29: 964530 | D29: 1086700 | E29: 865480 | F29: 1030647 | G29: 734510 | H29: 541890 | I29: 688661.48 | J29: 631434 | K29: 859844 | L29: 871341.45 | M29: 731644.08 | N29: 820 457,00 | O29: 9827139 | P29: 11044950 | Q29: =(P29-O29)/O29 -> 0.12392324 | R29: =P29 -> 11044950 | S29: =S28+S27+S26+S25+S24+S23 -> 11900000 | T29: =(S29-R29)/R29 -> 0.077415482
B30: Итого прибыль: | C30: 547 794,03 | D30: 1 168 544,55 | E30: 1 274 622,37 | F30: 1 251 472,33 | G30: 930 640,00 | H30: 730 419,99 | I30: 673 018,51 | J30: 1 075 819,83 | K30: 1 604 342,85 | L30: 1 613 465,55 | M30: 1 570 021,93 | N30: 1 597 877,03 | O30: 14038039 | P30: 16658389 | Q30: =(P30-O30)/O30 -> 0.18666071 | R30: =P30 -> 16658389 | S30: =S18-S29 -> 26826626 | T30: =(S30-R30)/R30 -> 0.61039734
B31: Рентабельность: | C31: 23% | D31: 37% | E31: 43% | F31: 38% | G31: 36% | H31: 37% | I31: 31% | J31: 40% | K31: 42% | L31: 41% | M31: 48% | N31: 43% | O31: 0.39 | P31: 0.42 | Q31: =(P31-O31)/O31 -> 0.076923077 | R31: =P31 -> 0.42 | S31: =S30/S11 -> 0.47300158 | T31: =(S31-R31)/R31 -> 0.12619424
R32: =P32
B33: Операционные расходы | R33: =P33
C34: Январь 2024 | D34: Февраль 2024 | E34: Март 2024 | F34: Апрель 2024 | G34: Май 2024 | H34: Июнь 2024 | I34: Июль 2024 | J34: Август 2024 | K34: Сентябрь 2024 | L34: Октябрь 2024 | M34: Ноябрь 2024 | N34: Декабрь 2024 | O34: 2024 | P34: 2025 | R34: =P34 -> 2025 | S34: бюджет 2026
B35: Выплата заработной платы(Операционные) | C35: 130 000,00 | D35: 130 000,00 | E35: 130 000,00 | F35: 130 000,00 | G35: 130 000,00 | H35: 130 000,00 | I35: 130 000,00 | J35: 130 000,00 | K35: 130 000,00 | L35: 130 000,00 | M35: 130 000,00 | N35: 130 000,00 | O35: 1560000 | P35: 1560000 | Q35: =(P35-O35)/O35 -> 0 | R35: =P35 -> 1560000 | S35: =P35*1.2 -> 1872000 | T35: =(S35-R35)/R35 -> 0.2 | U35: ростим зп | V35: Львов С.А.
B36: Итого Операционные расходы: | C36: 130 000,00 | D36: 130 000,00 | E36: 130 000,00 | F36: 130 000,00 | G36: 130 000,00 | H36: 130 000,00 | I36: 130 000,00 | J36: 130 000,00 | K36: 130 000,00 | L36: 130 000,00 | M36: 130 000,00 | N36: 130 000,00 | O36: 1560000 | P36: 1560000 | Q36: =(P36-O36)/O36 -> 0 | R36: =P36 -> 1560000 | S36: =P36 -> 1560000 | T36: =(S36-R36)/R36 -> 0
B37: Итого прибыль: | C37: 417 794,03 | D37: 1 038 544,55 | E37: 1 144 622,37 | F37: 1 121 472,33 | G37: 800 640,00 | H37: 600 419,99 | I37: 543 018,51 | J37: 945 819,83 | K37: 1 474 342,85 | L37: 1 483 465,55 | M37: 1 440 021,93 | N37: 1 467 877,03 | O37: 12478039 | P37: 15098389 | Q37: =(P37-O37)/O37 -> 0.20999696 | R37: =P37 -> 15098389 | S37: =S30-S36 -> 25266626 | T37: =(S37-R37)/R37 -> 0.67346498
B38: Рентабельность: | C38: 17% | D38: 33% | E38: 38% | F38: 34% | G38: 31% | H38: 30% | I38: 25% | J38: 35% | K38: 39% | L38: 38% | M38: 44% | N38: 40% | O38: 0.35 | P38: 0.38 | Q38: =(P38-O38)/O38 -> 0.085714286 | R38: =P38 -> 0.38 | S38: =S37/S11 -> 0.44549598 | T38: =(S38-R38)/R38 -> 0.17235784
R39: =P39
B40: Коммерческие расходы | R40: =P40
C41: Январь 2024 | D41: Февраль 2024 | E41: Март 2024 | F41: Апрель 2024 | G41: Май 2024 | H41: Июнь 2024 | I41: Июль 2024 | J41: Август 2024 | K41: Сентябрь 2024 | L41: Октябрь 2024 | M41: Ноябрь 2024 | N41: Декабрь 2024 | O41: 2024 | P41: 2025 | R41: =P41 -> 2025 | S41: бюджет 2026
B42: Выплата заработной платы(Развитие) | C42: 67 530,00 | D42: 113 330,00 | E42: 83000 | F42: 114 800,00 | G42: 157 400,00 | H42: 125 000,00 | I42: 79 350,00 | J42: 229 000,00 | K42: 265 000,00 | L42: 230 378,67 | M42: 220 750,00 | N42: 351 431,45 | O42: 2036970.1 | P42: 3842662.5 | Q42: =(P42-O42)/O42 -> 0.88645993 | R42: =P42 -> 3842662.5 | S42: =3840000 -> 3840000 | T42: =(S42-R42)/R42 -> -0.00069288416 | U42: Комер дир + 2 ОП | V42: Макшанова Л.М.
...

Sheet Помесячно Заполнить ответственн
A1: 0 | B1: Ответственный | C1: Месяц | D1: Квартал | E1: План | F1: Факт | G1: Комментарий
A2: 01.1.Выручка от продаж разработки | B2: Макшанова Л.М. | C2: 01.Январь | D2: 1 | E2: ='Макшанова'!H37 -> 0
A3: 01.2.Выручка от продаж разработки | B3: Сысоев В.С. | C3: 01.Январь | D3: 1 | E3: 1927665 | F3: 1927665 | H3: по плану видно что будет в районе 2 млн
A4: 02.1.Выручка сервера | B4: Макшанова Л.М. | C4: 01.Январь | D4: 1 | E4: ='Макшанова'!H39 -> 20000 | F4: 20000
A5: 03.1.Выручка коробки | B5: Макшанова Л.М. | C5: 01.Январь | D5: 1 | E5: ='Макшанова'!H43 -> 71800 | F5: 71800
A6: 04.1.Выручка поддержка | B6: Макшанова Л.М. | C6: 01.Январь | D6: 1 | E6: ='Макшанова'!H57 -> 83400 | F6: 83400
A7: 05.1.Выручка продукты | B7: Макшанова Л.М. | C7: 01.Январь | D7: 1 | E7: ='Макшанова'!H79 -> 53100 | F7: 53100
A8: 06.Себестоимость от продаж | B8: Макшанова Л.М. | C8: 01.Январь | D8: 1 | E8: =J8*0.35*(-1) -> -674682.75 | F8: -554535.54 | J8: =E3+E2 -> 1927665
A9: 07.Себестоимость коробки | B9: Макшанова Л.М. | C9: 01.Январь | D9: 1 | E9: =E5*0.5*(-1) -> -35900 | F9: -34865
A10: 08.Простой | B10: Макшанова Л.М. | C10: 01.Январь | D10: 1 | E10: -250000 | F10: -408840
A11: 09.Оплата попадосов | B11: Сысоев В.С. | C11: 01.Январь | D11: 1 | E11: -50000 | F11: -50000
A12: 10.Выплата заработной платы разработка | B12: Сысоев В.С. | C12: 01.Январь | D12: 1 | E12: -119740 | F12: -119740 | H12: в концепции что это оплата за работу специалиста по поддержке посчитано по средней ставке поддержки 3200 и плана 100 тысяч из расчета что 100% идет в ЗП по средней ствке аналитики 1350
A13: 11.Оплата аналитики | B13: Сысоев В.С. | C13: 01.Январь | D13: 1 | E13: -111020 | F13: -111020 | H13: цена часа 3200 | J13: =0+J8 -> 1927665
A14: 12.Откат ментам | B14: Павлова Д.И. | C14: 01.Январь | D14: 1 | E14: -333333.33 | F14: -100340
A15: 13.Бонус отдела продаж | B15: Макшанова Л.М. | C15: 01.Январь | D15: 1 | E15: -20000 | F15: 0
A16: 14.Выплата заработной платы(Операционные) | B16: Львов С.А. | C16: 01.Январь | D16: 1 | E16: -130000 | F16: -130000
A17: 15.Выплата заработной платы(Развитие) | B17: Макшанова Л.М. | C17: 01.Январь | D17: 1 | E17: -320000 | F17: -212500
A18: 16.Маркетинг | B18: Львов С.А. | C18: 01.Январь | D18: 1 | E18: 0 | F18: 0
A19: 17.RND | B19: Львов С.А. | C19: 01.Январь | D19: 1 | E19: 0 | F19: 0
A20: 18.Налоги | B20: Павлова Д.И. | C20: 01.Январь | D20: 1 | E20: -300000 | F20: -150000
A21: 19.Аренда серверов | B21: Гатих П.С. | C21: 01.Январь | D21: 1 | E21: -5834 | F21: -5225
A22: 20.Транспорт | B22: Павлова Д.И. | C22: 01.Январь | D22: 1 | E22: -4100 | F22: 0
A23: 21.Аренда офиса | B23: Павлова Д.И. | C23: 01.Январь | D23: 1 | E23: -87000 | F23: -86536
A24: 22.Связь | B24: Гатих П.С. | C24: 01.Январь | D24: 1 | E24: -17000 | F24: -12333.61
A25: 23.Офис | B25: Гатих П.С. | C25: 01.Январь | D25: 1 | E25: -41660 | F25: -106803
... A27: 25.Комисии | B27: Павлова Д.И. | C27: 01.Январь | D27: 1 | E27: -8300 | F27: -23800
A28: 25.Обучение | B28: Львов С.А. | C28: 01.Январь | D28: 1 | F28: 0
A29: 26.Налоги ЗП | B29: Павлова Д.И. | C29: 01.Январь | D29: 1 | E29: -300000 | F29: -385000
A30: 19.Аренда серверов | B30: Гатих П.С. | C30: 02.Февраль | D30: 1 | E30: -5834 | F30: -5225
A31: 01.1.Выручка от продаж разработки | B31: Макшанова Л.М. | C31: 02.Февраль | D31: 1 | E31: ='Макшанова'!L37 -> 182820 | F31: 0
A32: 02.1.Выручка сервера | B32: Макшанова Л.М. | C32: 02.Февраль | D32: 1 | E32: ='Макшанова'!L39 -> 25600 | F32: 19200
A33: 03.1.Выручка коробки | B33: Макшанова Л.М. | C33: 02.Февраль | D33: 1 | E33: ='Макшанова'!L43 -> 221400 | F33: 0
A34: 04.1.Выручка поддержка | B34: Макшанова Л.М. | C34: 02.Февраль | D34: 1 | E34: ='Макшанова'!L57 -> 38000 | F34: 57600
A35: 05.1.Выручка продукты | B35: Макшанова Л.М. | C35: 02.Февраль | D35: 1 | E35: ='Макшанова'!L79 -> 123900 | F35: 0
A36: 06.Себестоимость от продаж | B36: Сысоев В.С. | C36: 02.Февраль | D36: 1 | E36: =(E57+E31)*0.35*(-1) -> -941787 | F36: -679260.02 | J36: =E31+E58 -> 890570
A37: 07.Себестоимость коробки | B37: Макшанова Л.М. | C37: 02.Февраль | D37: 1 | E37: =E33*0.5*(-1) -> -110700 | F37: 0
A38: 08.Простой | B38: Сысоев В.С. | C38: 02.Февраль | D38: 1 | E38: -150000 | F38: -185100
A39: 09.Оплата попадосов | B39: Сысоев В.С. | C39: 02.Февраль | D39: 1 | E39: -100000 | F39: -74100
A40: 10.Выплата заработной платы разработка | B40: Сысоев В.С. | C40: 02.Февраль | D40: 1 | E40: -42180 | F40: -119500 | H40: в концепции что это оплата за работу специалиста по поддержке посчитано по средней ставке поддержки 3200 и плана 100 тысяч из расчета что 100% идет в ЗП по средней ствке аналитики 1350
A41: 11.Оплата аналитики | B41: Сысоев В.С. | C41: 02.Февраль | D41: 1 | E41: =E57*200/3300*(-1) -> -152000 | F41: -137040 | H41: цена часа 3300 | J41: =0+J36 -> 890570
...

Sheet Поквартально
A35: ПОМЕСЯЧНО

Sheet Инфо20-06.Себестоимость от прод
A1: 0 | B1: Ответственный | C1: Месяц | D1: Квартал | E1: План | F1: Факт | G1: Комментарий
A2: 06.Себестоимость от продаж разработки | B2: Сысоев В.С. | C2: 05.Май | D2: 2 | E2: -928200 | F2: -1437760

Sheet Макшанова
B1: Продажи
H2: Январь 2024 | L2: Февраль 2024 | O2: Март 2024 | R2: Апрель 2024 | U2: Май 2024 | X2: Июнь 2024 | AA2: Июль 2024 | AD2: Август 2024 | AG2: Сентябрь 2024 | AJ2: Октябрь 2024 | AM2: Ноябрь 2024 | AP2: Декабрь 2024 | AS2: План ИТОГО | AT2: бюджет 2026 | AU2: Ответсвенный
C3: Договор | D3: Дата | E3: часы январь | F3: Ставка | G3: % повышения | H3: План | I3: Факт | J3: Комментарий | K3: часы февраль | L3: План | M3: Факт | N3: Комментарий | O3: План | P3: Факт | Q3: Комментарий | R3: План | S3: Факт | T3: Комментарий | U3: План | V3: Факт | W3: Комментарий | X3: План | Y3: Факт | Z3: Комментарий | AA3: План | AB3: Факт | AC3: Комментарий | AD3: План | AE3: Факт | AF3: Комментарий | AG3: План | AH3: Факт | AI3: Комментарий | AJ3: План | AK3: Факт | AL3: Комментарий | AM3: План | AN3: Факт | AO3: Комментарий | AP3: План | AQ3: Факт | AR3: Комментарий | AS3: План Итого
B4: Выручка от продаж разработки | H4: =H37 -> 0 | I4: 0 | J4: 0 | L4: 297 850,00 | M4: 0 | N4: 0 | O4: 814 650,00 | P4: 0 | Q4: 0 | R4: 986 200,00 | S4: 0 | T4: 0 | U4: 663 050,00 | V4: 0 | W4: 0 | X4: 759 992,00 | Y4: 0 | Z4: 0 | AA4: 629 000,00 | AB4: 0 | AC4: 0 | AD4: 896 934,00 | AE4: 0 | AF4: 0 | AG4: 782 750,00 | AH4: 0 | AI4: 0 | AJ4: 816 550,00 | AK4: 0 | AL4: 0 | AM4: 883 492,00 | AN4: 0 | AO4: 0 | AP4: 672 042,00 | AQ4: 0 | AS4: 8670400 | AT4: 47 315 721,00 | AU4: Макшанова Л.М.
A5: 1 | B5: X-COM | C5: - | D5: - | E5: 550 | F5: 3000 | G5: 0 | H5: =E5*F5 -> 1650000
A6: 2 | B6: АРТИС | C6: не нашла | D6: - | E6: 150 | F6: 2800 | G6: 20 (3360р)
A7: 3 | B7: Симон Электрик | C7: 1С/0111/2023 | D7: 45231 | E7: 30 | F7: 3700 | G7: 10,81 (4100р)
A8: 4 | B8: Кертинг РУС | C8: 0808/2024 | D8: 46000 | E8: 57 | F8: 3600 | G8: -
A9: 5 | B9: Доза | C9: 25/07/2024-1 | D9: 45498 | E9: 40 | F9: 3000 | G9: 20 (3600)
A10: 6 | B10: Металл Сервис | C10: 28/05/2025-1 | D10: 45805 | E10: 5 | F10: 3570 | G10: 5 (3570)
A11: 7 | B11: Хольц-Хаус | F11: 3300 | G11: -
B12: Хольц-Хаус Урал | C12: 02/06/2025-3 | D12: 45810 | E12: 1 | F12: 3300 | G12: -
B13: Хольц Хаус Москва | C13: 02/06/2025-5 | D13: 45810 | E13: 1 | F13: 3300 | G13: -
B14: Хольц Хаус Северо-Запад | C14: 02/06/2025-6 | D14: 45810 | E14: 1 | F14: 3300 | G14: -
B15: Хольц Эстейт | C15: 02/06/2025-2 | D15: 45810 | E15: 1 | F15: 3300 | G15: -
B16: Хольц Солюшенс | C16: 02/06/2025-4 (не подписан) | D16: 45810 | E16: 1 | F16: 3300 | G16: -
B17: Хольц Констракшн | C17: 02/06/2025-1 | D17: 45810 | E17: 1 | F17: 3300 | G17: -
A18: 8 | B18: РЭК | E18: 20 | F18: 4140 | G18: 15 (4140)
A19: 9 | B19: СТГ ГВАРД | E19: 0 | F19: 4140 | G19: 15 (4140)
A20: 10 | B20: АО «НФ АК ПРАКТИК» | E20: 0 | F20: 3600 | G20: -
A21: 11 | B21: Соглашение | E21: 40 | F21: 3800 | G21: 5,5 (3800)
A22: 12 | B22: ГК Керамогранит | E22: 10 | F22: 3000 | G22: 20 (3600)
A23: 13 | B23: Армтек | E23: 12.5 | F23: 3300 | G23: -
A24: 14 | B24: У-УАЗ | F24: 2700
A25: 15 | B25: Телеинвест | E25: 30 | F25: 3600 | G25: -
A26: 16 | B26: Гагава Ресторантс | F26: 3300 | G26: не работаем | I26: 0
A27: 17 | B27: АО «Атомспецтранс» | G27: не работаем
A28: 18 | B28: МикроЭм Технологии | G28: не работаем
B29: НОВЫЕ Разработка | AS29: 12000000
A30: 19 | B30: ИП Колосов | E30: 23 | F30: 3990 | G30: новые | L30: =3950*18 -> 71100 | AS30: =I30+L30+O30+R30+U30+X30+AA30+AD30+AG30+AJ30+AM30+AP30 -> 71100 | AU30: Макшанова Л.М.
B31: Примум Мебель | E31: 18 | F31: 3990 | L31: =E31*F31 -> 71820 | AS31: =I31+L31+O31+R31+U31+X31+AA31+AD31+AG31+AJ31+AM31+AP31 -> 71820
A32: 20 | B32: Алимп | E32: 5 | F32: 3990 | G32: новые | L32: =E32*F32 -> 19950 | AS32: =I32+L32+O32+R32+U32+X32+AA32+AD32+AG32+AJ32+AM32+AP32 -> 19950
A33: 21 | B33: ПандаЭкспо | E33: =25 -> 25 | F33: 3990 | O33: =E33*F33 -> 99750 | S33: =F33*G33 -> 0 | T33: =G33*H33 -> 0 | V33: =I33*J33 -> 0 | AS33: =I33+L33+O33+R33+U33+X33+AA33+AD33+AG33+AJ33+AM33+AP33 -> 99750
A34: 22 | B34: ООО "АДЕН МЕТАЛ"» | E34: 30 | F34: 3800 | O34: =E34*F34 -> 114000 | R34: =E34*F34 -> 114000 | U34: 76000 | X34: 76000 | AA34: 76000 | AD34: 76000 | AG34: 76000 | AJ34: 76000 | AM34: 76000 | AP34: 76000 | AS34: =I34+L34+O34+R34+U34+X34+AA34+AD34+AG34+AJ34+AM34+AP34 -> 836000
A35: 23 | B35: АО КМПО "КАЗАНСКОЕ МОТОРОСТРОИТЕЛЬНОЕ ПРОИЗВОДСТВЕННОЕ ОБЪЕДИНЕНИЕ | E35: 30 | F35: 3800 | O35: =E35*F35 -> 114000 | R35: =E35*F35 -> 114000 | U35: =3800*20 -> 76000 | X35: =3800*30 -> 114000 | AA35: 76000 | AD35: 76000 | AG35: 76000 | AJ35: 76000 | AM35: 76000 | AP35: 76000 | AS35: =I35+L35+O35+R35+U35+X35+AA35+AD35+AG35+AJ35+AM35+AP35 -> 874000
A36: 24 | B36: Фортекс | E36: 100 | F36: 3800 | H36: 0 | L36: 19950 | O36: =E36*F36 -> 380000 | R36: =F35*E36 -> 380000 | U36: =3800*50 -> 190000 | X36: =3800*60 -> 228000 | AA36: =3800*80 -> 304000 | AD36: =3800*100 -> 380000 | AG36: =3800*120 -> 456000 | AJ36: =3800*150 -> 570000 | AM36: =3800*159 -> 604200 | AP36: =3800*170 -> 646000 | AS36: =I36+L36+O36+R36+U36+X36+AA36+AD36+AG36+AJ36+AM36+AP36 -> 4158150
B37: ИТОГО Новая разработка | H37: =H30+H32+H33+H34+H35+H36 -> 0 | I37: 0 | J37: 0 | K37: 0 | L37: =SUM(L30:L36) -> 182820 | M37: =SUM(M30:M36) -> 0 | N37: =SUM(N30:N36) -> 0 | O37: =SUM(O30:O36) -> 707750 | P37: =SUM(P30:P36) -> 0 | Q37: =SUM(Q30:Q36) -> 0 | R37: =SUM(R30:R36) -> 608000 | S37: =SUM(S30:S36) -> 0 | ... AS37: =SUM(AS30:AS36) -> 6130770
H38: 46048 | L38: фев.26 | O38: 46107 | R38: 46138 | U38: май.26 | X38: 46199 | AA38: 46229 | AD38: 46260 | AG38: сен.26 | AJ38: 46321 | AM38: ноя.26 | AP38: 46382 | AT38: бюджет 2026
B39: Выручка сервера | H39: =H40+H41+H42 -> 20000 | I39: =I40+I41+I42 -> 0 | J39: =J40+J41+J42 -> 0 | K39: =K40+K41+K42 -> 0 | L39: =L40+L41+L42 -> 25600 | M39: =M40+M41+M42 -> 0 | N39: =N40+N41+N42 -> 0 | O39: =O40+O41+O42 -> 32000 | ... AS39: =AS40+AS41+AS42 -> 397600 | AT39: ='Бюджет 2026'!S7 -> 400000
B40: ООО "ЗЕЛПАК" | H40: =5000*3 -> 15000 | L40: =6400*3 -> 19200 | O40: =6400*3 -> 19200 | R40: =6400*3 -> 19200 | U40: =6400*3 -> 19200 | X40: =6400*3 -> 19200 | AA40: =6400*3 -> 19200 | AD40: =6400*3 -> 19200 | AG40: =6400*3 -> 19200 | AJ40: =6400*3 -> 19200 | AM40: =6400*3 -> 19200 | AP40: =6400*3 -> 19200 | AS40: =SUM(H40:AR40) -> 226200
...

Sheet Сысоев
H3: Икс ком | I3: Артис | J3: Симон | K3: Ууаз | L3: Газпром | M3: Прочее | N3: Средняя ставка | O3: Сезонность (справочно) | P3: План | Q3: аналитика Федоров
G4: Часы (предел) | H4: 450 | I4: 150 | J4: 40 | K4: 200 | L4: 77 | M4: 150 | Q4: =I4*150 -> 22500
C5: Я | D5: 1248000 | H5: 150 | I5: 100 | J5: 40 | K5: 0 | L5: 0 | M5: 100 | N5: 3200 | O5: 0.3 | P5: =(H5+I5+J5+K5+L5+M5)*N5 -> 1248000 | Q5: =I5*150 -> 15000
C6: Ф | D6: 2508000 | H6: 400 | I6: 100 | J6: 40 | K6: 50 | L6: 20 | M6: 150 | N6: 3300 | O6: 0.7 | P6: =(H6+I6+J6+K6+L6+M6)*N6 -> 2508000 | Q6: =I6*150 -> 15000
C7: М | D7: 3104000 | H7: 450 | I7: 150 | J7: 40 | K7: 100 | L7: 30 | M7: 200 | N7: 3200 | O7: 0.8 | P7: =(H7+I7+J7+K7+L7+M7)*N7 -> 3104000 | Q7: =I7*150 -> 22500
C8: А | D8: 3135000 | H8: 450 | I8: 130 | J8: 40 | K8: 100 | L8: 30 | M8: 200 | N8: 3300 | O8: 0.85 | P8: =(H8+I8+J8+K8+L8+M8)*N8 -> 3135000 | Q8: =I8*150 -> 19500
C9: М | D9: 2310000 | H9: 300 | I9: 100 | J9: 40 | K9: 100 | L9: 60 | M9: 100 | N9: 3300 | O9: 0.65 | P9: =(H9+I9+J9+K9+L9+M9)*N9 -> 2310000 | Q9: =I9*150 -> 15000
C10: И | D10: 3185000 | H10: 400 | I10: 120 | J10: 40 | K10: 150 | L10: 50 | M10: 150 | N10: 3500 | O10: 0.75 | P10: =(H10+I10+J10+K10+L10+M10)*N10 -> 3185000 | Q10: =I10*150 -> 18000
C11: И | D11: 3276000 | H11: 400 | I11: 120 | J11: 40 | K11: 150 | L11: 0 | M11: 150 | N11: 3600 | O11: 0.75 | P11: =(H11+I11+J11+K11+L11+M11)*N11 -> 3096000 | Q11: =I11*150 -> 18000
C12: А | D12: 3420000 | H12: 400 | I12: 100 | J12: 40 | K12: 150 | L12: 0 | M12: 200 | N12: 3600 | O12: 0.8 | P12: =(H12+I12+J12+K12+L12+M12)*N12 -> 3204000 | Q12: =I12*150 -> 15000
C13: С | D13: 4014500 | H13: 450 | I13: 100 | J13: 40 | K13: 200 | L13: 0 | M13: 230 | N13: 3700 | O13: 0.85 | P13: =(H13+I13+J13+K13+L13+M13)*N13 -> 3774000 | Q13: =I13*150 -> 15000
C14: О | D14: 4273500 | H14: 450 | I14: 150 | J14: 40 | K14: 200 | L14: 0 | M14: 250 | N14: 3700 | O14: 0.95 | P14: =(H14+I14+J14+K14+L14+M14)*N14 -> 4033000 | Q14: =I14*150 -> 22500
C15: Н | D15: 4712000 | H15: 480 | I15: 150 | J15: 40 | K15: 200 | L15: 0 | M15: 300 | N15: 3800 | O15: 0.95 | P15: =(H15+I15+J15+K15+L15+M15)*N15 -> 4446000 | Q15: =I15*150 -> 22500
C16: Д | D16: 5187000 | H16: 500 | I16: 150 | J16: 40 | K16: 250 | L16: 0 | M16: 350 | N16: 3800 | O16: 1.2 | P16: =(H16+I16+J16+K16+L16+M16)*N16 -> 4902000 | Q16: =I16*150 -> 22500
P17: =SUM(P5:P16) -> 38945000

Sheet копия заполнить отв. Макшанова
A1: 0 | B1: Ответственный | C1: Месяц | D1: Квартал | E1: План | F1: Факт | G1: Комментарий
A2: 01.1.Выручка от продаж разработки | B2: Макшанова Л.М. | C2: 01.Январь | D2: 1 | E2: ='Макшанова'!H37 -> 0
A3: 02.1.Выручка сервера | B3: Макшанова Л.М. | C3: 01.Январь | D3: 1 | E3: =5000*4 -> 20000
A4: 03.1.Выручка коробки | B4: Макшанова Л.М. | C4: 01.Январь | D4: 1 | E4: ='Бюджет 2026'!S8/12 -> 208333.33
A5: 04.1.Выручка поддержка | B5: Макшанова Л.М. | C5: 01.Январь | D5: 1 | E5: ='Бюджет 2026'!S9/12 -> 291666.67
A6: 05.1.Выручка продукты | B6: Макшанова Л.М. | C6: 01.Январь | D6: 1 | E6: =59000*2 -> 118000
A7: 06.Себестоимость от продаж | B7: Сысоев В.С. | C7: 01.Январь | D7: 1 | E7: =J7*0.35*(-1) -> -212800 | J7: =E2+E29 -> 608000
A8: 07.Себестоимость коробки | B8: Макшанова Л.М. | C8: 01.Январь | D8: 1 | E8: =E4/0.5*(-1) -> -416666.67
A9: 13.Бонус отдела продаж | B9: Макшанова Л.М. | C9: 01.Январь | D9: 1 | E9: -20000
A10: 15.Выплата заработной платы(Развитие) | B10: Макшанова Л.М. | C10: 01.Январь | D10: 1 | E10: -320000
A11: 01.1.Выручка от продаж разработки | B11: Макшанова Л.М. | C11: 02.Февраль | D11: 1 | E11: ='Макшанова'!L37 -> 182820
A12: 02.1.Выручка сервера | B12: Макшанова Л.М. | C12: 02.Февраль | D12: 1 | E12: 30500
A13: 03.1.Выручка коробки | B13: Макшанова Л.М. | C13: 02.Февраль | D13: 1 | E13: ='Бюджет 2026'!S8/12 -> 208333.33
A14: 04.1.Выручка поддержка | B14: Макшанова Л.М. | C14: 02.Февраль | D14: 1 | E14: ='Бюджет 2026'!S9/12 -> 291666.67
A15: 05.1.Выручка продукты | B15: Макшанова Л.М. | C15: 02.Февраль | D15: 1 | E15: =59000*3 -> 177000
A16: 06.Себестоимость от продаж | B16: Сысоев В.С. | C16: 02.Февраль | D16: 1 | E16: =J16*0.35*(-1) -> -183687 | J16: =E11+E38 -> 524820
A17: 07.Себестоимость коробки | B17: Макшанова Л.М. | C17: 02.Февраль | D17: 1 | E17: =E13*0.5*(-1) -> -104166.67
A18: 13.Бонус отдела продаж | B18: Макшанова Л.М. | C18: 02.Февраль | D18: 1 | E18: -33333.333
A19: 15.Выплата заработной платы(Развитие) | B19: Макшанова Л.М. | C19: 02.Февраль | D19: 1 | E19: -320000
A20: 01.1.Выручка от продаж разработки | B20: Макшанова Л.М. | C20: 03.Март | D20: 1 | E20: ='Макшанова'!O37 -> 707750
A21: 02.1.Выручка сервера | B21: Макшанова Л.М. | C21: 03.Март | D21: 1 | E21: =30500+6100 -> 36600
A22: 03.1.Выручка коробки | B22: Макшанова Л.М. | C22: 03.Март | D22: 1 | E22: ='Бюджет 2026'!S8/12 -> 208333.33
A23: 04.1.Выручка поддержка | B23: Макшанова Л.М. | C23: 03.Март | D23: 1 | E23: =E5 -> 291666.67
A24: 05.1.Выручка продукты | B24: Макшанова Л.М. | C24: 03.Март | D24: 1 | E24: ='Бюджет 2026'!S10/12 -> 250000
A25: 06.Себестоимость от продаж | B25: Сысоев В.С. | C25: 03.Март | D25: 1 | E25: =J25*0.35*(-1) -> -394012.5 | J25: =E20+E47 -> 1125750
A26: 07.Себестоимость коробки | B26: Макшанова Л.М. | C26: 03.Март | D26: 1 | E26: =E22*0.5*(-1) -> -104166.67
A27: 13.Бонус отдела продаж | B27: Макшанова Л.М. | C27: 03.Март | D27: 1 | E27: -33333.333
A28: 15.Выплата заработной платы(Развитие) | B28: Макшанова Л.М. | C28: 03.Март | D28: 1 | E28: -320000
A29: 01.1.Выручка от продаж разработки | B29: Макшанова Л.М. | C29: 04.Апрель | D29: 2 | E29: ='Макшанова'!R37 -> 608000
A30: 02.1.Выручка сервера | B30: Макшанова Л.М. | C30: 04.Апрель | D30: 2 | E30: =30500+6100 -> 36600
A31: 03.1.Выручка коробки | B31: Макшанова Л.М. | C31: 04.Апрель | D31: 2 | E31: ='Бюджет 2026'!S8/12 -> 208333.33
A32: 04.1.Выручка поддержка | B32: Макшанова Л.М. | C32: 04.Апрель | D32: 2 | E32: ='Бюджет 2026'!S9/12 -> 291666.67
A33: 05.1.Выручка продукты | B33: Макшанова Л.М. | C33: 04.Апрель | D33: 2 | E33: ='Бюджет 2026'!S10/12 -> 250000
A34: 06.Себестоимость от продаж | B34: Сысоев В.С. | C34: 04.Апрель | D34: 2 | E34: =J34*0.35*(-1) -> -359100 | J34: =E29+E56 -> 1026000
A35: 07.Себестоимость коробки | B35: Макшанова Л.М. | C35: 04.Апрель | D35: 2 | E35: =E13*0.5*(-1) -> -104166.67
A36: 13.Бонус отдела продаж | B36: Макшанова Л.М. | C36: 04.Апрель | D36: 2 | E36: -33333.333
A37: 15.Выплата заработной платы(Развитие) | B37: Макшанова Л.М. | C37: 04.Апрель | D37: 2 | E37: -320000
A38: 01.1.Выручка от продаж разработки | B38: Макшанова Л.М. | C38: 05.Май | D38: 2 | E38: ='Макшанова'!U37 -> 342000
A39: 02.1.Выручка сервера | B39: Макшанова Л.М. | C39: 05.Май | D39: 2 | E39: 36600
A40: 03.1.Выручка коробки | B40: Макшанова Л.М. | C40: 05.Май | D40: 2 | E40: ='Бюджет 2026'!S8/12 -> 208333.33
...

Sheet Отклонение от  плана ЛСА
B1: Отклонение плана рук от плана ЛСА
C3: План ЛСА | D3: Отклонение
C4: 12000000 | D4: =B4-C4 -> -5869230
C5: 35186000 | D5: =B5-C5 -> 901665
C6: 400000 | D6: =B6-C6 -> -2400
C7: 2500000 | D7: =B7-C7 -> -902800
C8: 3500000 | D8: =B8-C8 -> -2903600
C9: 3000000 | D9: =B9-C9 -> -981600
C10: 16739095 | D10: =B10+C10 -> 1157643
C11: 1250000 | D11: =B11+C11 -> 321800
C12: 1000000 | D12: =B12+C12 -> 226400
C13: 500000 | D13: =B13+C13 -> 475000
C14: 3000000 | D14: =B14+C14 -> 1920000
C15: 3000000 | D15: =B15+C15 -> 2350000
C16: 4000000 | D16: =B16+C16 -> 2277340
C17: 400000 | D17: =B17+C17 -> -1883311.1
C18: 1872000 | D18: =B18+C18 -> -2128000
C19: 3840000 | D19: =B19+C19 -> 3453333.3
C20: 1000000 | D20: =B20+C20 -> -560000
C21: 1000000 | D21: =B21+C21 -> -2840000
... C31: 3970100.5 | D31: =B31+C31 -> 3700000.5
C32: =SUM(C4:C31) -> 1.090973e+08 | D32: =SUM(D4:D31) -> -1511586.8

Sheet Для ПД
D1: 1 | J1: 2 | P1: 3 | V1: 4
D2: Январь | F2: Февраль | H2: Март | J2: Апрель | L2: Май | N2: Июнь | P2: Июль | R2: Август | T2: Сентябрь | V2: Октябрь | X2: Ноябрь | Z2: Декабрь | AB2: ИТОГО
B3: бюджет 2026 | C3: Ответсвенный | D3: План | E3: Факт | F3: План | G3: Факт | H3: План | I3: Факт | J3: План | K3: Факт | L3: План | M3: Факт | N3: План | O3: Факт | P3: План | Q3: Факт | R3: План | S3: Факт | T3: План | U3: Факт | V3: План | W3: Факт | X3: План | Y3: Факт | Z3: План | AA3: Факт | AB3: План | AC3: Факт
A4: Выручка от продаж разработки | B4: 47315721 | C4: Макшанова Л.М. | AB4: =B4 -> 47315721 | AC4: =E4+G4+I4+K4+M4+O4+Q4+S4+U4+W4+Y4+AA4 -> 0
A5: Выручка сервера | B5: 400000 | C5: Макшанова Л.М. | AB5: =B5 -> 400000 | AC5: =E5+G5+I5+K5+M5+O5+Q5+S5+U5+W5+Y5+AA5 -> 0
A6: Выручка коробки | B6: 2500000 | C6: Макшанова Л.М. | AB6: =B6 -> 2500000 | AC6: =E6+G6+I6+K6+M6+O6+Q6+S6+U6+W6+Y6+AA6 -> 0
A7: Выручка поддержка | B7: 3500000 | C7: Макшанова Л.М. | AB7: =B7 -> 3500000 | AC7: =E7+G7+I7+K7+M7+O7+Q7+S7+U7+W7+Y7+AA7 -> 0
A8: Выручка продукты | B8: 3000000 | C8: Макшанова Л.М. | AB8: =B8 -> 3000000 | AC8: =E8+G8+I8+K8+M8+O8+Q8+S8+U8+W8+Y8+AA8 -> 0
A9: Себестоимость от продаж | B9: 16739095 | C9: Сысоев В.С. | AB9: =B9 -> 16739095 | AC9: =E9+G9+I9+K9+M9+O9+Q9+S9+U9+W9+Y9+AA9 -> 0
A10: Себестоимость коробки | B10: 1250000 | C10: Макшанова Л.М. | AB10: =B10 -> 1250000 | AC10: =E10+G10+I10+K10+M10+O10+Q10+S10+U10+W10+Y10+AA10 -> 0
A11: Простой | B11: 1000000 | C11: Сысоев В.С. | AB11: =B11 -> 1000000 | AC11: =E11+G11+I11+K11+M11+O11+Q11+S11+U11+W11+Y11+AA11 -> 0
A12: Оплата попадосов | B12: 500000 | C12: Сысоев В.С. | AB12: =B12 -> 500000 | AC12: =E12+G12+I12+K12+M12+O12+Q12+S12+U12+W12+Y12+AA12 -> 0
A13: Выплата заработной платы разработка | B13: 3000000 | C13: Сысоев В.С. | AB13: =B13 -> 3000000 | AC13: =E13+G13+I13+K13+M13+O13+Q13+S13+U13+W13+Y13+AA13 -> 0
A14: Оплата аналитики | B14: 3000000 | C14: Сысоев В.С. | AB14: =B14 -> 3000000 | AC14: =E14+G14+I14+K14+M14+O14+Q14+S14+U14+W14+Y14+AA14 -> 0
A15: Откат ментам | B15: 4000000 | C15: Павлова Д.И. | AB15: =B15 -> 4000000 | AC15: =E15+G15+I15+K15+M15+O15+Q15+S15+U15+W15+Y15+AA15 -> 0
... A30: Налоги ЗП | B30: 3970100.5 | C30: Павлова Д.И. | AB30: =B30 -> 3970100.5 | AC30: =E30+G30+I30+K30+M30+O30+Q30+S30+U30+W30+Y30+AA30 -> 0
A34: 01.1.Выручка от продаж разработки | B34: 47315721
A35: 01.2.Выручка от продаж разработки
A36: 02.1.Выручка сервера | B36: 400000
A37: 02.2.Выручка сервера
A38: 03.1.Выручка коробки | B38: 2500000
A39: 03.2.Выручка коробки
A40: 04.1.Выручка поддержка | B40: 3500000
A41: 04.2.Выручка поддержка
A42: 05.1.Выручка продукты | B42: 3000000
A43: 05.2.Выручка продукты
A44: 06.Себестоимость от продаж | B44: 16739095
A45: 07.Себестоимость коробки | B45: 1250000
A46: 08.Простой | B46: 1000000
A47: 09.Оплата попадосов | B47: 500000
A48: 10.Выплата заработной платы разработка | B48: 3000000
A49: 11.Оплата аналитики | B49: 3000000
A50: 12.Откат ментам | B50: 4000000
A51: 13.Бонус отдела продаж | B51: 400000
A52: 14.Выплата заработной платы(Операционные) | B52: 1872000
A53: 15.Выплата заработной платы(Развитие) | B53: 3840000
A54: 16.Маркетинг | B54: 1000000
A55: 17.RND | B55: 1000000
... A65: 26.Налоги ЗП | B65: 3970100.5
A67: ЗП | B67: мес | C67: официальные | D67: самозанятые | E67: Нал | F67: налог зп
...
